<?xml version="1.0"?>
<sdf version='1.6'>
  <model name='diablo'>
    <pose>0 0 0.3 0 0 0</pose>
  <!--  
    <joint name="ground_fix" type="fixed">
    	<pose>0 0 1 0 0 0</pose>
        <parent>world</parent>
        <child>Body</child>
    </joint>
  -->
    <link name='Body'>
      <pose frame=''>0 0 0 0 0 0</pose>
      <inertial>
        <mass>6.72372</mass>
        <inertia>
          <ixx>0.04835304544</ixx>
          <ixy>-0.00000187046</ixy>
          <ixz>-0.00263123506</ixz>
          <iyy>0.07156251226</iyy>
          <iyz>0.00000709833</iyz>
          <izz>0.07239192173</izz>
        </inertia>
        <pose frame=''>0.01243 0.00015 -0.00675 0 0 0</pose>
      </inertial>
      <self_collide>0</self_collide>
      <kinematic>0</kinematic>
      <gravity>1</gravity>
      <visual name='visual'>
        <pose frame=''>0 0 0 0 0 0</pose>
        <material>
          <script>
            <name>Gazebo/DarkGrey</name>
            <uri>file://media/materials/scripts/gazebo.material</uri>
          </script>
        </material>
        <geometry>
          <mesh>
            <uri>model://diablo_arm/STL/Body.stl</uri>
          </mesh>
        </geometry>
      </visual>
      <collision name='collision'>
        <laser_retro>0</laser_retro>
        <max_contacts>10</max_contacts>
        <pose frame=''>0 0 0 0 0 0</pose>
        <geometry>
          <mesh>
            <uri>model://diablo_arm/STL/Body.stl</uri>
          </mesh>
        </geometry>
        <surface>
          <friction>
            <ode>
              <mu>0</mu>
              <mu2>0</mu2>
              <fdir1>0 0 0</fdir1>
              <slip1>0</slip1>
              <slip2>0</slip2>
            </ode>
            <torsional>
              <coefficient>1</coefficient>
              <patch_radius>0</patch_radius>
              <surface_radius>0</surface_radius>
              <use_patch_radius>1</use_patch_radius>
              <ode>
                <slip>0</slip>
              </ode>
            </torsional>
          </friction>
          <bounce>
            <restitution_coefficient>0</restitution_coefficient>
            <threshold>1e+06</threshold>
          </bounce>
          <contact>
            <collide_without_contact>0</collide_without_contact>
            <collide_without_contact_bitmask>1</collide_without_contact_bitmask>
            <collide_bitmask>1</collide_bitmask>
            <ode>
              <soft_cfm>0</soft_cfm>
              <soft_erp>0.2</soft_erp>
              <kp>1e+13</kp>
              <kd>1</kd>
              <max_vel>0.01</max_vel>
              <min_depth>0</min_depth>
            </ode>
            <bullet>
              <split_impulse>1</split_impulse>
              <split_impulse_penetration_threshold>-0.01</split_impulse_penetration_threshold>
              <soft_cfm>0</soft_cfm>
              <soft_erp>0.2</soft_erp>
              <kp>1e+13</kp>
              <kd>1</kd>
            </bullet>
          </contact>
        </surface>
      </collision>
    </link>
   
    <link name='Leg0_R'>
      <pose frame=''>0 -0.1238 0  0 0.7853981634 0</pose>
      <inertial>
        <mass>2.46054</mass>
        <inertia>
          <ixx>0.00853721554</ixx>
          <ixy>-0.00000557176</ixy>
          <ixz>-0.00000007947</ixz>
          <iyy>0.00817363920</iyy>
          <iyz>0.00020599673</iyz>
          <izz>0.00794292074</izz>
        </inertia>
        <pose frame=''>-0.00036 0.01353 -0.00417 0 -0 0</pose>
      </inertial>
      <self_collide>0</self_collide>
      <kinematic>0</kinematic>
      <gravity>1</gravity>
      <visual name='visual'>
        <pose frame=''>0 0 0 0 -0 0</pose>
        <geometry>
          <mesh>
            <uri>model://diablo_arm/STL/Leg_0.stl</uri>
          </mesh>
        </geometry>
      </visual>
    </link>

    <link name='Leg0_L'>
      <pose frame=''>0 0.12375 0 0 -0.7853981634 3.141592653</pose>
      <inertial>
        <mass>2.46054</mass>
        <inertia>
          <ixx>0.00853721554</ixx>
          <ixy>-0.00000557176</ixy>
          <ixz>-0.00000007947</ixz>
          <iyy>0.00817363920</iyy>
          <iyz>0.00020599673</iyz>
          <izz>0.00794292074</izz>
        </inertia>
        <pose frame=''>-0.00036 0.01353 -0.00417 0 -0 0</pose>
      </inertial>
      <self_collide>0</self_collide>
      <kinematic>0</kinematic>
      <gravity>1</gravity>
      <visual name='visual'>
        <pose frame=''>0 0 0 0 -0 0</pose>
        <geometry>
          <mesh>
            <uri>model://diablo_arm/STL/Leg_0.stl</uri>
          </mesh>
        </geometry>
      </visual>
    </link>

    <link name='Leg1_R'>
      <pose frame=''>0 -0.17625 0 0 0.7853981634 3.141592653</pose>
      <inertial>
        <mass>1.24694</mass>
        <inertia>
          <ixx>0.00293798860</ixx>
          <ixy>-0.00003883141</ixy>
          <ixz>0.00009809991</ixz>
          <iyy>0.00343777913</iyy>
          <iyz>-0.00004625489</iyz>
          <izz>0.00226057779</izz>
        </inertia>
        <pose frame=''>-0.00012 -0.02373 -0.00534 0 -0 0</pose>
      </inertial>
      <self_collide>0</self_collide>
      <kinematic>0</kinematic>
      <gravity>1</gravity>
      <visual name='visual'>
        <material>
          <script>
            <name>Gazebo/DarkGrey</name>
            <uri>file://media/materials/scripts/gazebo.material</uri>
          </script>
        </material>
        <pose frame=''>0 0 0 0 -0 0</pose>
        <geometry>
          <mesh>
            <uri>model://diablo_arm/STL/Leg_1_R.stl</uri>
          </mesh>
        </geometry>
      </visual>
      <!-- <collision name='collision'>
        <laser_retro>0</laser_retro>
        <max_contacts>10</max_contacts>
        <pose frame=''>0 0 0 0 -0 0</pose>
        <geometry>
          <mesh>
            <uri>model://diablo_arm/STL/Leg_1_L.STL</uri>
          </mesh>
        </geometry>
        <surface>
          <friction>
            <ode>
              <mu>0</mu>
              <mu2>0</mu2>
              <fdir1>0 0 0</fdir1>
              <slip1>0</slip1>
              <slip2>0</slip2>
            </ode>
            <torsional>
              <coefficient>1</coefficient>
              <patch_radius>0</patch_radius>
              <surface_radius>0</surface_radius>
              <use_patch_radius>1</use_patch_radius>
              <ode>
                <slip>0</slip>
              </ode>
            </torsional>
          </friction>
          <bounce>
            <restitution_coefficient>0</restitution_coefficient>
            <threshold>1e+06</threshold>
          </bounce>
          <contact>
            <collide_without_contact>0</collide_without_contact>
            <collide_without_contact_bitmask>1</collide_without_contact_bitmask>
            <collide_bitmask>1</collide_bitmask>
            <ode>
              <soft_cfm>0</soft_cfm>
              <soft_erp>0.2</soft_erp>
              <kp>1e+13</kp>
              <kd>1</kd>
              <max_vel>0.01</max_vel>
              <min_depth>0.001</min_depth>
            </ode>
          </contact>
        </surface>
      </collision> -->
    </link>

    <link name='Leg1_L'>
      <pose frame=''>0 0.17625 0 0 -0.7853981634 0</pose>
      <inertial>
        <mass>1.24694</mass>
        <inertia>
          <ixx>0.00282971660</ixx>
          <ixy>-0.00001808035</ixy>
          <ixz>-0.00009872009</ixz>
          <iyy>0.00344247372</iyy>
          <iyz>-0.00006052905</iyz>
          <izz>0.00214713102</izz>
        </inertia>
        <pose frame=''>0.00196 -0.02373 -0.00534 0 -0 0</pose>
      </inertial>
      <self_collide>0</self_collide>
      <kinematic>0</kinematic>
      <gravity>1</gravity>
      <visual name='visual'>
        <material>
          <script>
            <name>Gazebo/DarkGrey</name>
            <uri>file://media/materials/scripts/gazebo.material</uri>
          </script>
        </material>
        <pose frame=''>0 0 0 0 -0 0</pose>
        <geometry>
          <mesh>
            <uri>model://diablo_arm/STL/Leg_1_L.stl</uri>
          </mesh>
        </geometry>
      </visual>
      <!-- <collision name='collision'>
        <laser_retro>0</laser_retro>
        <max_contacts>10</max_contacts>
        <pose frame=''>0 0 0 0 -0 0</pose>
        <geometry>
          <mesh>
            <uri>model://diablo_arm/STL/Leg_1_R.STL</uri>
          </mesh>
        </geometry>
        <surface>
          <friction>
            <ode>
              <mu>0</mu>
              <mu2>0</mu2>
              <fdir1>0 0 0</fdir1>
              <slip1>0</slip1>
              <slip2>0</slip2>
            </ode>
            <torsional>
              <coefficient>1</coefficient>
              <patch_radius>0</patch_radius>
              <surface_radius>0</surface_radius>
              <use_patch_radius>1</use_patch_radius>
              <ode>
                <slip>0</slip>
              </ode>
            </torsional>
          </friction>
          <bounce>
            <restitution_coefficient>0</restitution_coefficient>
            <threshold>1e+06</threshold>
          </bounce>
          <contact>
            <collide_without_contact>0</collide_without_contact>
            <collide_without_contact_bitmask>1</collide_without_contact_bitmask>
            <collide_bitmask>1</collide_bitmask>
            <ode>
              <soft_cfm>0</soft_cfm>
              <soft_erp>0.2</soft_erp>
              <kp>1e+13</kp>
              <kd>1</kd>
              <max_vel>0.01</max_vel>
              <min_depth>0.001</min_depth>
            </ode>
          </contact>
        </surface>
      </collision> -->
    </link>

    <link name='Leg2_R'>
      <pose frame=''>-0.06363961031 -0.17625 -0.06363961031 0 -0.7853981634 0</pose>
      <inertial>
        <mass>0.10247</mass>
        <inertia>
          <ixx>0.00081266186</ixx>
          <ixy>0.00001334864</ixy>
          <ixz>0.00012964651</ixz>
          <iyy>0.00085532347</iyy>
          <iyz>0.00006246273</iyz>
          <izz>0.00006022942</izz>
        </inertia>
        <pose frame=''>-0.01628 -0.008 -0.07331 0 -0 0</pose>
      </inertial>
      <self_collide>0</self_collide>
      <kinematic>0</kinematic>
      <gravity>1</gravity>
      <visual name='visual'>
        <material>
          <script>
            <name>Gazebo/DarkGrey</name>
            <uri>file://media/materials/scripts/gazebo.material</uri>
          </script>
        </material>
        <pose frame=''>0 0 0 0 -0 0</pose>
        <geometry>
          <mesh>
            <uri>model://diablo_arm/STL/Leg_2.stl</uri>
          </mesh>
        </geometry>
      </visual>
      <!-- <collision name='collision'>
        <laser_retro>0</laser_retro>
        <max_contacts>10</max_contacts>
        <pose frame=''>0 0 0 0 -0 0</pose>
        <geometry>
          <mesh>
            <uri>model://diablo_arm/STL/Leg_2.STL</uri>
          </mesh>
        </geometry>
        <surface>
          <friction>
            <ode>
              <mu>0</mu>
              <mu2>0</mu2>
              <fdir1>0 0 0</fdir1>
              <slip1>0</slip1>
              <slip2>0</slip2>
            </ode>
            <torsional>
              <coefficient>1</coefficient>
              <patch_radius>0</patch_radius>
              <surface_radius>0</surface_radius>
              <use_patch_radius>1</use_patch_radius>
              <ode>
                <slip>0</slip>
              </ode>
            </torsional>
          </friction>
          <bounce>
            <restitution_coefficient>0</restitution_coefficient>
            <threshold>1e+06</threshold>
          </bounce>
          <contact>
            <collide_without_contact>0</collide_without_contact>
            <collide_without_contact_bitmask>1</collide_without_contact_bitmask>
            <collide_bitmask>1</collide_bitmask>
            <ode>
              <soft_cfm>0</soft_cfm>
              <soft_erp>0.2</soft_erp>
              <kp>1e+13</kp>
              <kd>1</kd>
              <max_vel>0.01</max_vel>
              <min_depth>0.001</min_depth>
            </ode>
          </contact>
        </surface>
      </collision> -->
    </link>

    <link name='Leg2_L'>
      <pose frame=''>-0.06363961031 0.19225 -0.06363961031 0 -0.7853981634 0</pose>
      <inertial>
        <mass>0.10247</mass>
        <inertia>
          <ixx>0.00081266186</ixx>
          <ixy>0.00001334864</ixy>
          <ixz>0.00012964651</ixz>
          <iyy>0.00085532347</iyy>
          <iyz>0.00006246273</iyz>
          <izz>0.00006022942</izz>
        </inertia>
        <pose frame=''>-0.01628 -0.008 -0.07331 0 -0 0</pose>
      </inertial>
      <self_collide>0</self_collide>
      <kinematic>0</kinematic>
      <gravity>1</gravity>
      <visual name='visual'>
        <material>
          <script>
            <name>Gazebo/DarkGrey</name>
            <uri>file://media/materials/scripts/gazebo.material</uri>
          </script>
        </material>
        <pose frame=''>0 0 0 0 -0 0</pose>
        <geometry>
          <mesh>
            <uri>model://diablo_arm/STL/Leg_2.stl</uri>
          </mesh>
        </geometry>
      </visual>
      <!-- <collision name='collision'>
        <laser_retro>0</laser_retro>
        <max_contacts>10</max_contacts>
        <pose frame=''>0 0 0 0 -0 0</pose>
        <geometry>
          <mesh>
            <uri>model://diablo_arm/STL/Leg_2.STL</uri>
          </mesh>
        </geometry>
        <surface>
          <friction>
            <ode>
              <mu>0</mu>
              <mu2>0</mu2>
              <fdir1>0 0 0</fdir1>
              <slip1>0</slip1>
              <slip2>0</slip2>
            </ode>
            <torsional>
              <coefficient>1</coefficient>
              <patch_radius>0</patch_radius>
              <surface_radius>0</surface_radius>
              <use_patch_radius>1</use_patch_radius>
              <ode>
                <slip>0</slip>
              </ode>
            </torsional>
          </friction>
          <bounce>
            <restitution_coefficient>0</restitution_coefficient>
            <threshold>1e+06</threshold>
          </bounce>
          <contact>
            <collide_without_contact>0</collide_without_contact>
            <collide_without_contact_bitmask>1</collide_without_contact_bitmask>
            <collide_bitmask>1</collide_bitmask>
            <ode>
              <soft_cfm>0</soft_cfm>
              <soft_erp>0.2</soft_erp>
              <kp>1e+13</kp>
              <kd>1</kd>
              <max_vel>0.01</max_vel>
              <min_depth>0.001</min_depth>
            </ode>
          </contact>
        </surface>
      </collision> -->
    </link>

    <link name='Leg3_R'>
      <pose frame=''>0 -0.2155 -0.1979898987 0 0.7853981634 0</pose>
      <inertial>
        <mass>1.29685</mass>
        <inertia>
          <ixx>0.00302829941</ixx>
          <ixy>-0.00003267530</ixy>
          <ixz>-0.00018726087</ixz>
          <iyy>0.00363170943</iyy>
          <iyz>-0.00016180170</iyz>
          <izz>0.00218077632</izz>
        </inertia>
        <pose frame=''>-0.00127 -0.02001 0.00598 0 -0 0</pose>
      </inertial>
      <self_collide>0</self_collide>
      <kinematic>0</kinematic>
      <gravity>1</gravity>
      <visual name='visual'>
        <material>
          <script>
            <name>Gazebo/Grey</name>
            <uri>file://media/materials/scripts/gazebo.material</uri>
          </script>
        </material>
        <pose frame=''>0 0 0 0 -0 0</pose>
        <geometry>
          <mesh>
            <uri>model://diablo_arm/STL/Leg_3.stl</uri>
          </mesh>
        </geometry>
      </visual>
      <!-- <collision name='collision'>
        <laser_retro>0</laser_retro>
        <max_contacts>10</max_contacts>
        <pose frame=''>0 0 0 0 -0 0</pose>
        <geometry>
          <mesh>
            <uri>model://diablo_arm/STL/Leg_3.STL</uri>
          </mesh>
        </geometry>
        <surface>
          <friction>
            <ode>
              <mu>0</mu>
              <mu2>0</mu2>
              <fdir1>0 0 0</fdir1>
              <slip1>0</slip1>
              <slip2>0</slip2>
            </ode>
            <torsional>
              <coefficient>1</coefficient>
              <patch_radius>0</patch_radius>
              <surface_radius>0</surface_radius>
              <use_patch_radius>1</use_patch_radius>
              <ode>
                <slip>0</slip>
              </ode>
            </torsional>
          </friction>
          <bounce>
            <restitution_coefficient>0</restitution_coefficient>
            <threshold>1e+06</threshold>
          </bounce>
          <contact>
            <collide_without_contact>0</collide_without_contact>
            <collide_without_contact_bitmask>1</collide_without_contact_bitmask>
            <collide_bitmask>1</collide_bitmask>
            <ode>
              <soft_cfm>0</soft_cfm>
              <soft_erp>0.2</soft_erp>
              <kp>1e+13</kp>
              <kd>1</kd>
              <max_vel>0.01</max_vel>
              <min_depth>0.001</min_depth>
            </ode>
          </contact>
        </surface>
      </collision> -->
    </link>

    <link name='Leg3_L'>
      <pose frame=''>0 0.2155 -0.1979898987 0 -0.7853981634 3.141592653</pose>
      <inertial>
        <mass>1.29685</mass>
        <inertia>
          <ixx>0.00302829941</ixx>
          <ixy>-0.00003267530</ixy>
          <ixz>-0.00018726087</ixz>
          <iyy>0.00363170943</iyy>
          <iyz>-0.00016180170</iyz>
          <izz>0.00218077632</izz>
        </inertia>
        <pose frame=''>-0.00127 -0.02001 0.00598 0 -0 0</pose>
      </inertial>
      <self_collide>0</self_collide>
      <kinematic>0</kinematic>
      <gravity>1</gravity>
      <visual name='visual'>
        <material>
          <script>
            <name>Gazebo/Grey</name>
            <uri>file://media/materials/scripts/gazebo.material</uri>
          </script>
        </material>
        <pose frame=''>0 0 0 0 -0 0</pose>
        <geometry>
          <mesh>
            <uri>model://diablo_arm/STL/Leg_3.stl</uri>
          </mesh>
        </geometry>
      </visual>
      <!-- <collision name='collision'>
        <laser_retro>0</laser_retro>
        <max_contacts>10</max_contacts>
        <pose frame=''>0 0 0 0 -0 0</pose>
        <geometry>
          <mesh>
            <uri>model://diablo_arm/STL/Leg_3.STL</uri>
          </mesh>
        </geometry>
        <surface>
          <friction>
            <ode>
              <mu>0</mu>
              <mu2>0</mu2>
              <fdir1>0 0 0</fdir1>
              <slip1>0</slip1>
              <slip2>0</slip2>
            </ode>
            <torsional>
              <coefficient>1</coefficient>
              <patch_radius>0</patch_radius>
              <surface_radius>0</surface_radius>
              <use_patch_radius>1</use_patch_radius>
              <ode>
                <slip>0</slip>
              </ode>
            </torsional>
          </friction>
          <bounce>
            <restitution_coefficient>0</restitution_coefficient>
            <threshold>1e+06</threshold>
          </bounce>
          <contact>
            <collide_without_contact>0</collide_without_contact>
            <collide_without_contact_bitmask>1</collide_without_contact_bitmask>
            <collide_bitmask>1</collide_bitmask>
            <ode>
              <soft_cfm>0</soft_cfm>
              <soft_erp>0.2</soft_erp>
              <kp>1e+13</kp>
              <kd>1</kd>
              <max_vel>0.01</max_vel>
              <min_depth>0.001</min_depth>
            </ode>
          </contact>
        </surface>
      </collision> -->
    </link>

    <link name='Wheel_R'>
      <pose frame=''>0 -0.24625 -0.1979898987 0 0 0</pose>
      <inertial>
        <mass>1.36187</mass>
        <inertia>
          <ixx>0.00349977</ixx>
          <ixy>0</ixy>
          <ixz>0</ixz>
          <iyy>0.00660656</iyy>
          <iyz>0</iyz>
          <izz>0.00349977</izz>
        </inertia>
        <pose frame=''>0 0 0 0 -0 0</pose>
      </inertial>
      <self_collide>0</self_collide>
      <kinematic>0</kinematic>
      <gravity>1</gravity>
      <visual name='visual'>
        <material>
          <script>
            <name>Gazebo/Red</name>
            <uri>file://media/materials/scripts/gazebo.material</uri>
          </script>
        </material>
        <pose frame=''>0 0 0 0 -0 0</pose>
        <geometry>
          <mesh>
            <uri>model://diablo_arm/STL/Wheel.stl</uri>
          </mesh>
        </geometry>
      </visual>
      <visual name='visual_guide'>
        <material>
          <script>
            <name>Gazebo/Black</name>
            <uri>file://media/materials/scripts/gazebo.material</uri>
          </script>
        </material>
        <pose frame=''>0.05 -0.03 0 0 -0 0</pose>
        <geometry>
		  <sphere>
		  	<radius>0.008</radius>
		  </sphere>
        </geometry>
      </visual>      
      <collision name='collision'>
        <laser_retro>0</laser_retro>
        <max_contacts>10</max_contacts>
        <pose frame=''>0 0 0 0 -0 0</pose>
        <geometry>
          <mesh>
            <uri>model://diablo_arm/STL/Wheel.stl</uri>
          </mesh>
        </geometry>
        <surface>
          <friction>
            <ode>
              <mu>0.6</mu>
              <mu2>0.6</mu2>
              <fdir1>0 0 0</fdir1>
              <slip1>0.0</slip1>
              <slip2>0.0</slip2>
            </ode>
            <torsional>
              <coefficient>1</coefficient>
              <patch_radius>0</patch_radius>
              <surface_radius>0</surface_radius>
              <use_patch_radius>1</use_patch_radius>
              <ode>
                <slip>0</slip>
              </ode>
            </torsional>
          </friction>
          <bounce>
            <restitution_coefficient>0</restitution_coefficient>
            <threshold>1e+06</threshold>
          </bounce>
          <contact>
            <collide_without_contact>0</collide_without_contact>
            <collide_without_contact_bitmask>1</collide_without_contact_bitmask>
            <collide_bitmask>65535</collide_bitmask>
            <ode>
              <soft_cfm>0</soft_cfm>
              <soft_erp>0.2</soft_erp>
              <kp>1e+13</kp>
              <kd>1</kd>
              <max_vel>0.01</max_vel>
              <min_depth>0.001</min_depth>
            </ode>
          </contact>
        </surface>
      </collision>
    </link>

    <link name='Wheel_L'>
      <pose frame=''>0 0.24625 -0.1979898987 0 0 3.141592653</pose>
      <inertial>
        <mass>1.36187</mass>
        <inertia>
          <ixx>0.00349977</ixx>
          <ixy>0</ixy>
          <ixz>0</ixz>
          <iyy>0.00660656</iyy>
          <iyz>0</iyz>
          <izz>0.00349977</izz>
        </inertia>
        <pose frame=''>0 0 0 0 -0 0</pose>
      </inertial>
      <self_collide>0</self_collide>
      <kinematic>0</kinematic>
      <gravity>1</gravity>
      <visual name='visual'>
        <material>
          <script>
            <name>Gazebo/Blue</name>
            <uri>file://media/materials/scripts/gazebo.material</uri>
          </script>
        </material>
        <pose frame=''>0 0 0 0 -0 0</pose>
        <geometry>
          <mesh>
            <uri>model://diablo_arm/STL/Wheel.stl</uri>
          </mesh>
        </geometry>
      </visual>
      <visual name='visual_guide'>
        <material>
          <script>
            <name>Gazebo/Black</name>
            <uri>file://media/materials/scripts/gazebo.material</uri>
          </script>
        </material>
        <pose frame=''>0.05 -0.03 0 0 -0 0</pose>
        <geometry>
		  <sphere>
		  	<radius>0.008</radius>
		  </sphere>
        </geometry>
      </visual>      
      <collision name='collision'>
        <laser_retro>0</laser_retro>
        <max_contacts>10</max_contacts>
        <pose frame=''>0 0 0 0 -0 0</pose>
        <geometry>
          <mesh>
            <uri>model://diablo_arm/STL/Wheel.stl</uri>
          </mesh>
        </geometry>
        <surface>
          <friction>
            <ode>
              <mu>0.6</mu>
              <mu2>0.6</mu2>
              <fdir1>0 0 0</fdir1>
              <slip1>0.0</slip1>
              <slip2>0.0</slip2>
            </ode>
            <torsional>
              <coefficient>1</coefficient>
              <patch_radius>0</patch_radius>
              <surface_radius>0</surface_radius>
              <use_patch_radius>1</use_patch_radius>
              <ode>
                <slip>0</slip>
              </ode>
            </torsional>
          </friction>
          <bounce>
            <restitution_coefficient>0</restitution_coefficient>
            <threshold>1e+06</threshold>
          </bounce>
          <contact>
            <collide_without_contact>0</collide_without_contact>
            <collide_without_contact_bitmask>1</collide_without_contact_bitmask>
            <collide_bitmask>65535</collide_bitmask>
            <ode>
              <soft_cfm>0</soft_cfm>
              <soft_erp>0.2</soft_erp>
              <kp>1e+13</kp>
              <kd>1</kd>
              <max_vel>0.01</max_vel>
              <min_depth>0.001</min_depth>
            </ode>
          </contact>
        </surface>
      </collision>
    </link>

    <joint name='Motor0_L' type='revolute'>
      <parent>Body</parent>
      <child>Leg0_L</child>
      <pose frame=''>0 0 0 0 -0 0</pose>
      <axis>
        <xyz>0 1 0</xyz>
        <use_parent_model_frame>1</use_parent_model_frame>
        <limit>          
          <lower>-1.53</lower>
          <upper>1.56</upper>
          <effort>200</effort>
          <velocity>100</velocity>
        </limit>
        <dynamics>
          <damping>0</damping>
          <friction>0</friction>
        </dynamics>
      </axis>
      <physics>
        <ode>
          <limit>
            <cfm>0</cfm>
            <erp>0.2</erp>
          </limit>
          <suspension>
            <cfm>0</cfm>
            <erp>0.2</erp>
          </suspension>
        </ode>
      </physics>
    </joint>

    <joint name='Motor0_R' type='revolute'>
      <parent>Body</parent>
      <child>Leg0_R</child>
      <pose frame=''>0 0 0 0 -0 0</pose>
      <axis>
        <xyz>0 1 0</xyz>
        <use_parent_model_frame>1</use_parent_model_frame>
        <limit>          
          <lower>-1.53</lower>
          <upper>1.56</upper>
          <effort>200</effort>
          <velocity>100</velocity>
        </limit>
        <dynamics>
          <damping>0</damping>
          <friction>0</friction>
        </dynamics>
      </axis>
      <physics>
        <ode>
          <limit>
            <cfm>0</cfm>
            <erp>0.2</erp>
          </limit>
          <suspension>
            <cfm>0</cfm>
            <erp>0.2</erp>
          </suspension>
        </ode>
      </physics>
    </joint>

    <joint name='Motor1_L' type='revolute'>
      <parent>Leg0_L</parent>
      <child>Leg1_L</child>
      <pose frame=''>0 0 0 0 -0 0</pose>
      <axis>
        <xyz>0 1 0</xyz>
        <use_parent_model_frame>1</use_parent_model_frame>
        <limit>          
          <lower>-1.0</lower>
          <upper>1.0</upper>         
          <effort>1000</effort>
          <velocity>500</velocity>
        </limit>
        <dynamics>
          <damping>0</damping>
          <friction>0</friction>
        </dynamics>
      </axis>
      <physics>
        <ode>
          <limit>
            <cfm>0</cfm>
            <erp>0.2</erp>
          </limit>
          <suspension>
            <cfm>0</cfm>
            <erp>0.2</erp>
          </suspension>
        </ode>
      </physics>
    </joint>

    <joint name='Motor1_R' type='revolute'>
      <parent>Leg0_R</parent>
      <child>Leg1_R</child>
      <pose frame=''>0 0 0 0 -0 0</pose>
      <axis>
        <xyz>0 1 0</xyz>
        <use_parent_model_frame>1</use_parent_model_frame>
        <limit>          
          <lower>-1.0</lower>
          <upper>1.0</upper>
          <effort>1000</effort>
          <velocity>500</velocity>
        </limit>
        <dynamics>
          <damping>0</damping>
          <friction>0</friction>
        </dynamics>
      </axis>
      <physics>
        <ode>
          <limit>
            <cfm>0</cfm>
            <erp>0.2</erp>
          </limit>
          <suspension>
            <cfm>0</cfm>
            <erp>0.2</erp>
          </suspension>
        </ode>
      </physics>
    </joint>

    <joint name='J1_L' type='revolute'>
      <parent>Leg0_L</parent>
      <child>Leg2_L</child>
      <pose frame=''>0 0 0 0 -0 0</pose>
      <axis>
        <xyz>0 1 0</xyz>
        <use_parent_model_frame>1</use_parent_model_frame>        
        <limit>
          <lower>-0.5</lower>
          <upper>0.5</upper>
        </limit>       
        <dynamics>
          <damping>0.2</damping>
          <friction>0.1</friction>
        </dynamics>
      </axis>
      <physics>
        <ode>
          <suspension>
            <cfm>0</cfm>
            <erp>0.2</erp>
          </suspension>
        </ode>
      </physics>
    </joint>

    <joint name='J1_R' type='revolute'>
      <parent>Leg0_R</parent>
      <child>Leg2_R</child>
      <pose frame=''>0 0 0 0 -0 0</pose>
      <axis>
        <xyz>0 1 0</xyz>
        <use_parent_model_frame>1</use_parent_model_frame>
        <limit>
          <lower>-0.5</lower>
          <upper>0.5</upper>
        </limit>       
        <dynamics>
          <damping>0.2</damping>
          <friction>0.1</friction>
        </dynamics>
      </axis>
      <physics>
        <ode>
          <suspension>
            <cfm>0</cfm>
            <erp>0.2</erp>
          </suspension>
        </ode>
      </physics>
    </joint>

    <joint name='J2_L' type='revolute'>
      <parent>Leg1_L</parent>
      <child>Leg3_L</child>
      <pose frame=''>0 0 0.14 0 -0 0</pose>
      <axis>
        <xyz>0 1 0</xyz>
        <use_parent_model_frame>1</use_parent_model_frame>
        <limit>
          <lower>-0.5</lower>
          <upper>0.5</upper>
        </limit>       
        <dynamics>
          <damping>0.2</damping>
          <friction>0.1</friction>
        </dynamics>
      </axis>
      <physics>
        <ode>
          <suspension>
            <cfm>0</cfm>
            <erp>0.2</erp>
          </suspension>
        </ode>
      </physics>
    </joint>

    <joint name='J2_R' type='revolute'>
      <parent>Leg1_R</parent>
      <child>Leg3_R</child>
      <pose frame=''>0 0 0.14 0 -0 0</pose>
      <axis>
        <xyz>0 1 0</xyz>
        <use_parent_model_frame>1</use_parent_model_frame>
        <limit>
          <lower>-0.5</lower>
          <upper>0.5</upper>
        </limit>       
        <dynamics>
          <damping>0.2</damping>
          <friction>0.1</friction>
        </dynamics>
      </axis>
      <physics>
        <ode>
          <suspension>
            <cfm>0</cfm>
            <erp>0.2</erp>
          </suspension>
        </ode>
      </physics>
    </joint>

    <joint name='J3_L' type='revolute'>
      <parent>Leg2_L</parent>
      <child>Leg3_L</child>
      <pose frame=''>0 0 0.05 0 -0 0</pose>
      <axis>
        <xyz>0 1 0</xyz>
        <use_parent_model_frame>1</use_parent_model_frame>
        <limit>
          <lower>-0.5</lower>
          <upper>0.5</upper>
        </limit>       
        <dynamics>
          <damping>0.2</damping>
          <friction>0.1</friction>
        </dynamics>
      </axis>
      <physics>
        <ode>
          <limit>
            <cfm>0</cfm>
            <erp>0.2</erp>
          </limit>
          <suspension>
            <cfm>0</cfm>
            <erp>0.2</erp>
          </suspension>
        </ode>
      </physics>
    </joint>

    <joint name='J3_R' type='revolute'>
      <parent>Leg2_R</parent>
      <child>Leg3_R</child>
      <pose frame=''>0 0 0.05 0 -0 0</pose>
      <axis>
        <xyz>0 1 0</xyz>
        <use_parent_model_frame>1</use_parent_model_frame>
        <limit>
          <lower>-0.5</lower>
          <upper>0.5</upper>
        </limit>       
        <dynamics>
          <damping>0.2</damping>
          <friction>0.1</friction>
        </dynamics>
      </axis>
      <physics>
        <ode>
          <limit>
            <cfm>0</cfm>
            <erp>0.2</erp>
          </limit>
          <suspension>
            <cfm>0</cfm>
            <erp>0.2</erp>
          </suspension>
        </ode>
      </physics>
    </joint>

    <joint name='Motor2_L' type='revolute'>
      <parent>Leg3_L</parent>
      <child>Wheel_L</child>
      <pose frame=''>0 0 0 0 -0 0</pose>
      <axis>
        <xyz>0 1 0</xyz>
        <use_parent_model_frame>1</use_parent_model_frame>
        <dynamics>
          <damping>0</damping>
          <friction>0</friction>
        </dynamics>
        <limit>
          <effort>1000</effort>
          <velocity>1000</velocity>
        </limit>       
      </axis>
      <physics>
        <ode>
          <limit>
            <cfm>0</cfm>
            <erp>0.2</erp>
          </limit>
          <suspension>
            <cfm>0</cfm>
            <erp>0.2</erp>
          </suspension>
        </ode>
      </physics>
    </joint>

    <joint name='Motor2_R' type='revolute'>
      <parent>Leg3_R</parent>
      <child>Wheel_R</child>
      <pose frame=''>0 0 0 0 -0 0</pose>
      <axis>
        <xyz>0 1 0</xyz>
        <use_parent_model_frame>1</use_parent_model_frame>
        <limit>
          <effort>1000</effort>
          <velocity>1000</velocity>
        </limit>       
      </axis>
      <physics>
        <ode>
          <limit>
            <cfm>0</cfm>
            <erp>0.2</erp>
          </limit>
          <suspension>
            <cfm>0</cfm>
            <erp>0.2</erp>
          </suspension>
        </ode>
      </physics>
    </joint>

  <plugin name="M1R" filename="libgeneric_motor_plugin.so">
  	<namespace>diablo</namespace>
  	<joint_name>Motor0_R</joint_name>
  	<Kp>180.0</Kp>
  	<Kd>10.0</Kd>
  	<Ki>3.0</Ki>
  </plugin>
  <plugin name="M2R" filename="libgeneric_motor_plugin.so">
  	<namespace>diablo</namespace>
  	<joint_name>Motor1_R</joint_name>
  	<Kp>150.0</Kp>
  	<Kd>10.0</Kd>
  	<Ki>3.0</Ki>
  </plugin>  
  <plugin name="M3R" filename="libgeneric_motor_plugin.so">
  	<namespace>diablo</namespace>
  	<joint_name>Motor2_R</joint_name>
  	<Kp>20.0</Kp>
  	<Kd>2.0</Kd>
  	<Ki>0.5</Ki>
  </plugin>
  <plugin name="M1L" filename="libgeneric_motor_plugin.so">
  	<namespace>diablo</namespace>
  	<joint_name>Motor0_L</joint_name>
  	<Kp>180.0</Kp>
  	<Kd>10.0</Kd>
  	<Ki>3.0</Ki>
  </plugin>
  <plugin name="M2L" filename="libgeneric_motor_plugin.so">
  	<namespace>diablo</namespace>
  	<joint_name>Motor1_L</joint_name>
  	<Kp>150.0</Kp>
  	<Kd>10.0</Kd>
  	<Ki>3.0</Ki>
  </plugin>
  <plugin name="M3L" filename="libgeneric_motor_plugin.so">
  	<namespace>diablo</namespace>
  	<joint_name>Motor2_L</joint_name>
  	<Kp>20.0</Kp>
  	<Kd>2.0</Kd>
  	<Ki>0.5</Ki>
  </plugin>

    <joint name="imu_joint" type="fixed">
      <parent>Body</parent>
      <child>imu_link</child>
    </joint>
    <link name="imu_link">
      <inertial>
        <pose>0 0 0 0 0 0</pose>
        <mass>0.1</mass>
        <inertia> 
		    <ixx>0.001</ixx>
		    <ixy>0</ixy> 
		    <ixz>0</ixz> 
		    <iyy>0.001</iyy> 
		    <iyz>0</iyz>
		    <izz>0.002</izz>
        </inertia>
      </inertial>
      <visual name="imu_visual">
      	<pose>0 0 0 0 0 0</pose>
      	<geometry>
      	  <sphere>
      	  	<radius>0.01</radius>
      	  </sphere>
      	</geometry>
      </visual>
      <collision name="imu_collision">
      	<pose>0 0 0 0 0 0</pose>
      	<geometry>
      	  <sphere>
      	    <radius>0.01</radius>
      	  </sphere>
      	</geometry>
      </collision>      
      <sensor name='imu_sensor' type='imu'>
        <always_on>1</always_on>
        <update_rate>1000</update_rate>
        <pose>0 0 0 0 -0 0</pose>
			<topic>__default_topic__</topic>
		    <plugin filename="libgazebo_ros_imu_sensor.so" name="imu_plugin">
		      <topicName>imu</topicName>
		      <bodyName>imu_link</bodyName>
		      <updateRateHZ>1000.0</updateRateHZ>
		      <gaussianNoise>0.0001</gaussianNoise>
		      <xyzOffset>0 0 0</xyzOffset>
		      <rpyOffset>0 0 0</rpyOffset>
		      <frameName>imu_link</frameName>
		      <initialOrientationAsReference>false</initialOrientationAsReference>
		    </plugin>
      </sensor>
    </link>
    <plugin name="low_lvl_controller" filename="liblow_ctrl_plugin.so">
    	<namespace>diablo</namespace>
    </plugin>

    <model name='j2n6s300'>
    <joint name='connect_root_and_world' type='fixed'>
      <pose relative_to='__model__'>0 0 0.10 0 0 0</pose>
      <parent>Body</parent>
      <child>root</child>
    </joint>
    <link name='root'>
      <pose relative_to='connect_root_and_world'>0 0 0 0 -0 0</pose>
      <inertial>
        <pose>0 0 0.1255 0 -0 0</pose>
        <mass>0.46784</mass>
        <inertia>
          <ixx>0.000951271</ixx>
          <ixy>0</ixy>
          <ixz>0</ixz>
          <iyy>0.000951271</iyy>
          <iyz>0</iyz>
          <izz>0.000374272</izz>
        </inertia>
      </inertial>
      <collision name='root_fixed_joint_lump__j2n6s300_link_base_collision'>
        <pose>0 0 0 0 -0 0</pose>
        <geometry>
          <mesh>
            <scale>1 1 1</scale>
            <uri>model://j2n6s300/meshes/base.dae</uri>
          </mesh>
        </geometry>
      </collision>
      <visual name='root_fixed_joint_lump__j2n6s300_link_base_visual'>
        <pose>0 0 0 0 -0 0</pose>
        <geometry>
          <mesh>
            <scale>1 1 1</scale>
            <uri>model://j2n6s300/meshes/base.dae</uri>
          </mesh>
        </geometry>
      </visual>
    </link>
    <joint name='j2n6s300_joint_1' type='fixed'>
      <pose relative_to='root'>0 0 0.15675 3.14159 0 3.14159</pose>
      <parent>root</parent>
      <child>j2n6s300_link_1</child>
      <axis>
        <xyz>0 0 1</xyz>
        <limit>
          <effort>40</effort>
          <velocity>0.628319</velocity>
          <lower>-1e+16</lower>
          <upper>1e+16</upper>
        </limit>
        <dynamics>
          <damping>0</damping>
          <friction>0</friction>
          <spring_reference>0</spring_reference>
          <spring_stiffness>0</spring_stiffness>
        </dynamics>
      </axis>
      <physics>
        <provide_feedback>1</provide_feedback>
        <ode>
          <limit>
            <cfm>0</cfm>
            <erp>0.2</erp>
          </limit>
          <provide_feedback>1</provide_feedback>
        </ode>
      </physics>
    </joint>
    <link name='j2n6s300_link_1'>
      <pose relative_to='j2n6s300_joint_1'>0 0 0 0 -0 0</pose>
      <inertial>
        <pose>0 -0.002 -0.0605 0 -0 0</pose>
        <mass>0.7477</mass>
        <inertia>
          <ixx>0.00152032</ixx>
          <ixy>0</ixy>
          <ixz>0</ixz>
          <iyy>0.00152032</iyy>
          <iyz>0</iyz>
          <izz>0.00059816</izz>
        </inertia>
      </inertial>
      <collision name='j2n6s300_link_1_collision'>
        <pose>0 0 0 0 -0 0</pose>
        <geometry>
          <mesh>
            <scale>1 1 1</scale>
            <uri>model://j2n6s300/meshes/shoulder.dae</uri>
          </mesh>
        </geometry>
      </collision>
      <visual name='j2n6s300_link_1_visual'>
        <pose>0 0 0 0 -0 0</pose>
        <geometry>
          <mesh>
            <scale>1 1 1</scale>
            <uri>model://j2n6s300/meshes/shoulder.dae</uri>
          </mesh>
        </geometry>
      </visual>
      <visual name='j2n6s300_link_1_visual_1'>
        <pose>0 0 0 0 -0 0</pose>
        <geometry>
          <mesh>
            <scale>1 1 1</scale>
            <uri>model://j2n6s300/meshes/ring_big.dae</uri>
          </mesh>
        </geometry>
      </visual>
    </link>
    <joint name='j2n6s300_joint_2' type='fixed'>
      <pose relative_to='j2n6s300_link_1'>0 0.0016 -0.11875 1.5708 -0 3.14159</pose>
      <parent>j2n6s300_link_1</parent>
      <child>j2n6s300_link_2</child>
      <axis>
        <xyz>0 0 1</xyz>
        <limit>
          <lower>0.820305</lower>
          <upper>5.46288</upper>
          <effort>80</effort>
          <velocity>0.628319</velocity>
        </limit>
        <dynamics>
          <damping>0</damping>
          <friction>0</friction>
          <spring_reference>0</spring_reference>
          <spring_stiffness>0</spring_stiffness>
        </dynamics>
      </axis>
      <physics>
        <provide_feedback>1</provide_feedback>
        <ode>
          <limit>
            <cfm>0</cfm>
            <erp>0.2</erp>
          </limit>
          <provide_feedback>1</provide_feedback>
        </ode>
      </physics>
    </joint>
    <link name='j2n6s300_link_2'>
      <pose relative_to='j2n6s300_joint_2'>0 0 0 0 3.14159 0</pose>
      <inertial>
        <pose>0 -0.2065 -0.01 0 -0 0</pose>
        <mass>0.99</mass>
        <inertia>
          <ixx>0.0105022</ixx>
          <ixy>0</ixy>
          <ixz>0</ixz>
          <iyy>0.000792</iyy>
          <iyz>0</iyz>
          <izz>0.0105022</izz>
        </inertia>
      </inertial>
      <collision name='j2n6s300_link_2_collision'>
        <pose>0 0 0 0 -0 0</pose>
        <geometry>
          <mesh>
            <scale>1 1 1</scale>
            <uri>model://j2n6s300/meshes/arm.dae</uri>
          </mesh>
        </geometry>
      </collision>
      <visual name='j2n6s300_link_2_visual'>
        <pose>0 0 0 0 -0 0</pose>
        <geometry>
          <mesh>
            <scale>1 1 1</scale>
            <uri>model://j2n6s300/meshes/arm.dae</uri>
          </mesh>
        </geometry>
      </visual>
      <visual name='j2n6s300_link_2_visual_1'>
        <pose>0 0 0 0 -0 0</pose>
        <geometry>
          <mesh>
            <scale>1 1 1</scale>
            <uri>model://j2n6s300/meshes/ring_big.dae</uri>
          </mesh>
        </geometry>
      </visual>
    </link>
    <joint name='j2n6s300_joint_3' type='fixed'>
      <pose relative_to='j2n6s300_link_2'>0 -0.41 0 0 3.14159 3.14159</pose>
      <parent>j2n6s300_link_2</parent>
      <child>j2n6s300_link_3</child>
      <axis>
        <xyz>0 0 1</xyz>
        <limit>
          <lower>0.331613</lower>
          <upper>5.95157</upper>
          <effort>40</effort>
          <velocity>0.628319</velocity>
        </limit>
        <dynamics>
          <damping>0</damping>
          <friction>0</friction>
          <spring_reference>0</spring_reference>
          <spring_stiffness>0</spring_stiffness>
        </dynamics>
      </axis>
      <physics>
        <provide_feedback>1</provide_feedback>
        <ode>
          <limit>
            <cfm>0</cfm>
            <erp>0.2</erp>
          </limit>
          <provide_feedback>1</provide_feedback>
        </ode>
      </physics>
    </joint>
    <link name='j2n6s300_link_3'>
      <pose relative_to='j2n6s300_joint_3'>0 0 0 0 -0 0</pose>
      <inertial>
        <pose>0 0.081 -0.0086 0 -0 0</pose>
        <mass>0.6763</mass>
        <inertia>
          <ixx>0.00142022</ixx>
          <ixy>0</ixy>
          <ixz>0</ixz>
          <iyy>0.000304335</iyy>
          <iyz>0</iyz>
          <izz>0.00142022</izz>
        </inertia>
      </inertial>
      <collision name='j2n6s300_link_3_collision'>
        <pose>0 0 0 0 -0 0</pose>
        <geometry>
          <mesh>
            <scale>1 1 1</scale>
            <uri>model://j2n6s300/meshes/forearm.dae</uri>
          </mesh>
        </geometry>
      </collision>
      <visual name='j2n6s300_link_3_visual'>
        <pose>0 0 0 0 -0 0</pose>
        <geometry>
          <mesh>
            <scale>1 1 1</scale>
            <uri>model://j2n6s300/meshes/forearm.dae</uri>
          </mesh>
        </geometry>
      </visual>
      <visual name='j2n6s300_link_3_visual_1'>
        <pose>0 0 0 0 -0 0</pose>
        <geometry>
          <mesh>
            <scale>1 1 1</scale>
            <uri>model://j2n6s300/meshes/ring_big.dae</uri>
          </mesh>
        </geometry>
      </visual>
    </link>
    <joint name='j2n6s300_joint_4' type='fixed'>
      <pose relative_to='j2n6s300_link_3'>0 0.2073 -0.0114 -1.5708 -0 3.14159</pose>
      <parent>j2n6s300_link_3</parent>
      <child>j2n6s300_link_4</child>
      <axis>
        <xyz>0 0 1</xyz>
        <limit>
          <effort>20</effort>
          <velocity>0.837758</velocity>
          <lower>-1e+16</lower>
          <upper>1e+16</upper>
        </limit>
        <dynamics>
          <damping>0</damping>
          <friction>0</friction>
          <spring_reference>0</spring_reference>
          <spring_stiffness>0</spring_stiffness>
        </dynamics>
      </axis>
      <physics>
        <provide_feedback>1</provide_feedback>
        <ode>
          <limit>
            <cfm>0</cfm>
            <erp>0.2</erp>
          </limit>
          <provide_feedback>1</provide_feedback>
        </ode>
      </physics>
    </joint>
    <link name='j2n6s300_link_4'>
      <pose relative_to='j2n6s300_joint_4'>0 0 0 0 -0 0</pose>
      <inertial>
        <pose>0 -0.037 -0.0642 0 -0 0</pose>
        <mass>0.426367</mass>
        <inertia>
          <ixx>7.73497e-05</ixx>
          <ixy>0</ixy>
          <ixz>0</ixz>
          <iyy>7.73497e-05</iyy>
          <iyz>0</iyz>
          <izz>0.0001428</izz>
        </inertia>
      </inertial>
      <collision name='j2n6s300_link_4_collision'>
        <pose>0 0 0 0 -0 0</pose>
        <geometry>
          <mesh>
            <scale>1 1 1</scale>
            <uri>model://j2n6s300/meshes/wrist.dae</uri>
          </mesh>
        </geometry>
      </collision>
      <visual name='j2n6s300_link_4_visual'>
        <pose>0 0 0 0 -0 0</pose>
        <geometry>
          <mesh>
            <scale>1 1 1</scale>
            <uri>model://j2n6s300/meshes/wrist.dae</uri>
          </mesh>
        </geometry>
      </visual>
      <visual name='j2n6s300_link_4_visual_1'>
        <pose>0 0 0 0 -0 0</pose>
        <geometry>
          <mesh>
            <scale>1 1 1</scale>
            <uri>model://j2n6s300/meshes/ring_small.dae</uri>
          </mesh>
        </geometry>
      </visual>
    </link>
    <joint name='j2n6s300_joint_5' type='fixed'>
      <pose relative_to='j2n6s300_link_4'>0 -0.03703 -0.06414 1.0472 -0 3.14159</pose>
      <parent>j2n6s300_link_4</parent>
      <child>j2n6s300_link_5</child>
      <axis>
        <xyz>0 0 1</xyz>
        <limit>
          <effort>20</effort>
          <velocity>0.837758</velocity>
          <lower>-1e+16</lower>
          <upper>1e+16</upper>
        </limit>
        <dynamics>
          <damping>0</damping>
          <friction>0</friction>
          <spring_reference>0</spring_reference>
          <spring_stiffness>0</spring_stiffness>
        </dynamics>
      </axis>
      <physics>
        <provide_feedback>1</provide_feedback>
        <ode>
          <limit>
            <cfm>0</cfm>
            <erp>0.2</erp>
          </limit>
          <provide_feedback>1</provide_feedback>
        </ode>
      </physics>
    </joint>
    <link name='j2n6s300_link_5'>
      <pose relative_to='j2n6s300_joint_5'>0 0 0 0 -0 0</pose>
      <inertial>
        <pose>0 -0.037 -0.0642 0 -0 0</pose>
        <mass>0.426367</mass>
        <inertia>
          <ixx>7.73497e-05</ixx>
          <ixy>0</ixy>
          <ixz>0</ixz>
          <iyy>7.73497e-05</iyy>
          <iyz>0</iyz>
          <izz>0.0001428</izz>
        </inertia>
      </inertial>
      <collision name='j2n6s300_link_5_collision'>
        <pose>0 0 0 0 -0 0</pose>
        <geometry>
          <mesh>
            <scale>1 1 1</scale>
            <uri>model://j2n6s300/meshes/wrist.dae</uri>
          </mesh>
        </geometry>
      </collision>
      <visual name='j2n6s300_link_5_visual'>
        <pose>0 0 0 0 -0 0</pose>
        <geometry>
          <mesh>
            <scale>1 1 1</scale>
            <uri>model://j2n6s300/meshes/wrist.dae</uri>
          </mesh>
        </geometry>
      </visual>
      <visual name='j2n6s300_link_5_visual_1'>
        <pose>0 0 0 0 -0 0</pose>
        <geometry>
          <mesh>
            <scale>1 1 1</scale>
            <uri>model://j2n6s300/meshes/ring_small.dae</uri>
          </mesh>
        </geometry>
      </visual>
    </link>
    <joint name='j2n6s300_joint_6' type='fixed'>
      <pose relative_to='j2n6s300_link_5'>0 -0.03703 -0.06414 1.0472 -0 3.14159</pose>
      <parent>j2n6s300_link_5</parent>
      <child>j2n6s300_link_6</child>
      <axis>
        <xyz>0 0 1</xyz>
        <limit>
          <effort>20</effort>
          <velocity>0.837758</velocity>
          <lower>-1e+16</lower>
          <upper>1e+16</upper>
        </limit>
        <dynamics>
          <damping>0</damping>
          <friction>0</friction>
          <spring_reference>0</spring_reference>
          <spring_stiffness>0</spring_stiffness>
        </dynamics>
      </axis>
      <physics>
        <provide_feedback>1</provide_feedback>
        <ode>
          <limit>
            <cfm>0</cfm>
            <erp>0.2</erp>
          </limit>
          <provide_feedback>1</provide_feedback>
        </ode>
      </physics>
    </joint>
    <link name='j2n6s300_link_6'>
      <pose relative_to='j2n6s300_joint_6'>0 0 0 0 -0 0</pose>
      <inertial>
        <pose>0 0 -0.06 0 -0 0</pose>
        <mass>0.99</mass>
        <inertia>
          <ixx>0.000345324</ixx>
          <ixy>0</ixy>
          <ixz>0</ixz>
          <iyy>0.000345324</iyy>
          <iyz>0</iyz>
          <izz>0.0005816</izz>
        </inertia>
      </inertial>
      <collision name='j2n6s300_link_6_collision'>
        <pose>0 0 0 0 -0 0</pose>
        <geometry>
          <mesh>
            <scale>1 1 1</scale>
            <uri>model://j2n6s300/meshes/hand_3finger.dae</uri>
          </mesh>
        </geometry>
      </collision>
      <visual name='j2n6s300_link_6_visual'>
        <pose>0 0 0 0 -0 0</pose>
        <geometry>
          <mesh>
            <scale>1 1 1</scale>
            <uri>model://j2n6s300/meshes/hand_3finger.dae</uri>
          </mesh>
        </geometry>
      </visual>
      <visual name='j2n6s300_link_6_visual_1'>
        <pose>0 0 0 0 -0 0</pose>
        <geometry>
          <mesh>
            <scale>1 1 1</scale>
            <uri>model://j2n6s300/meshes/ring_small.dae</uri>
          </mesh>
        </geometry>
      </visual>
    </link>
    <joint name='j2n6s300_joint_finger_1' type='fixed'>
      <pose relative_to='j2n6s300_link_6'>0.00279 0.03126 -0.11467 -1.70479 0.647614 1.67317</pose>
      <parent>j2n6s300_link_6</parent>
      <child>j2n6s300_link_finger_1</child>
      <axis>
        <xyz>0 0 1</xyz>
        <limit>
          <lower>0</lower>
          <upper>1.51</upper>
          <effort>2</effort>
          <velocity>1</velocity>
        </limit>
        <dynamics>
          <spring_reference>0</spring_reference>
          <spring_stiffness>0</spring_stiffness>
        </dynamics>
      </axis>
    </joint>
    <link name='j2n6s300_link_finger_1'>
      <pose relative_to='j2n6s300_joint_finger_1'>0 0 0 0 -0 0</pose>
      <inertial>
        <pose>0.022 0 0 0 -0 0</pose>
        <mass>0.01</mass>
        <inertia>
          <ixx>7.89997e-07</ixx>
          <ixy>0</ixy>
          <ixz>0</ixz>
          <iyy>7.89997e-07</iyy>
          <iyz>0</iyz>
          <izz>8e-08</izz>
        </inertia>
      </inertial>
      <collision name='j2n6s300_link_finger_1_collision'>
        <pose>0 0 0 0 -0 0</pose>
        <geometry>
          <mesh>
            <scale>1 1 1</scale>
            <uri>model://j2n6s300/meshes/finger_proximal.dae</uri>
          </mesh>
        </geometry>
      </collision>
      <visual name='j2n6s300_link_finger_1_visual'>
        <pose>0 0 0 0 -0 0</pose>
        <geometry>
          <mesh>
            <scale>1 1 1</scale>
            <uri>model://j2n6s300/meshes/finger_proximal.dae</uri>
          </mesh>
        </geometry>
      </visual>
    </link>
    <joint name='j2n6s300_joint_finger_tip_1' type='fixed'>
      <pose relative_to='j2n6s300_link_finger_1'>0.044 -0.003 0 0 -0 0</pose>
      <parent>j2n6s300_link_finger_1</parent>
      <child>j2n6s300_link_finger_tip_1</child>
      <axis>
        <xyz>0 0 1</xyz>
        <limit>
          <lower>0</lower>
          <upper>2</upper>
          <effort>2</effort>
          <velocity>1</velocity>
        </limit>
        <dynamics>
          <spring_reference>0</spring_reference>
          <spring_stiffness>0</spring_stiffness>
        </dynamics>
      </axis>
    </joint>
    <link name='j2n6s300_link_finger_tip_1'>
      <pose relative_to='j2n6s300_joint_finger_tip_1'>0 0 0 0 -0 0</pose>
      <inertial>
        <pose>0.022 0 0 0 -0 0</pose>
        <mass>0.01</mass>
        <inertia>
          <ixx>7.89997e-07</ixx>
          <ixy>0</ixy>
          <ixz>0</ixz>
          <iyy>7.89997e-07</iyy>
          <iyz>0</iyz>
          <izz>8e-08</izz>
        </inertia>
      </inertial>
      <collision name='j2n6s300_link_finger_tip_1_collision'>
        <pose>0 0 0 0 -0 0</pose>
        <geometry>
          <mesh>
            <scale>1 1 1</scale>
            <uri>model://j2n6s300/meshes/finger_distal.dae</uri>
          </mesh>
        </geometry>
      </collision>
      <visual name='j2n6s300_link_finger_tip_1_visual'>
        <pose>0 0 0 0 -0 0</pose>
        <geometry>
          <mesh>
            <scale>1 1 1</scale>
            <uri>model://j2n6s300/meshes/finger_distal.dae</uri>
          </mesh>
        </geometry>
      </visual>
    </link>
    <joint name='j2n6s300_joint_finger_2' type='fixed'>
      <pose relative_to='j2n6s300_link_6'>0.02226 -0.02707 -0.11482 -1.5708 0.649262 -1.38614</pose>
      <parent>j2n6s300_link_6</parent>
      <child>j2n6s300_link_finger_2</child>
      <axis>
        <xyz>0 0 1</xyz>
        <limit>
          <lower>0</lower>
          <upper>1.51</upper>
          <effort>2</effort>
          <velocity>1</velocity>
        </limit>
        <dynamics>
          <spring_reference>0</spring_reference>
          <spring_stiffness>0</spring_stiffness>
        </dynamics>
      </axis>
    </joint>
    <link name='j2n6s300_link_finger_2'>
      <pose relative_to='j2n6s300_joint_finger_2'>0 0 0 0 -0 0</pose>
      <inertial>
        <pose>0.022 0 0 0 -0 0</pose>
        <mass>0.01</mass>
        <inertia>
          <ixx>7.89997e-07</ixx>
          <ixy>0</ixy>
          <ixz>0</ixz>
          <iyy>7.89997e-07</iyy>
          <iyz>0</iyz>
          <izz>8e-08</izz>
        </inertia>
      </inertial>
      <collision name='j2n6s300_link_finger_2_collision'>
        <pose>0 0 0 0 -0 0</pose>
        <geometry>
          <mesh>
            <scale>1 1 1</scale>
            <uri>model://j2n6s300/meshes/finger_proximal.dae</uri>
          </mesh>
        </geometry>
      </collision>
      <visual name='j2n6s300_link_finger_2_visual'>
        <pose>0 0 0 0 -0 0</pose>
        <geometry>
          <mesh>
            <scale>1 1 1</scale>
            <uri>model://j2n6s300/meshes/finger_proximal.dae</uri>
          </mesh>
        </geometry>
      </visual>
    </link>
    <joint name='j2n6s300_joint_finger_tip_2' type='fixed'>
      <pose relative_to='j2n6s300_link_finger_2'>0.044 -0.003 0 0 -0 0</pose>
      <parent>j2n6s300_link_finger_2</parent>
      <child>j2n6s300_link_finger_tip_2</child>
      <axis>
        <xyz>0 0 1</xyz>
        <limit>
          <lower>0</lower>
          <upper>2</upper>
          <effort>2</effort>
          <velocity>1</velocity>
        </limit>
        <dynamics>
          <spring_reference>0</spring_reference>
          <spring_stiffness>0</spring_stiffness>
        </dynamics>
      </axis>
    </joint>
    <link name='j2n6s300_link_finger_tip_2'>
      <pose relative_to='j2n6s300_joint_finger_tip_2'>0 0 0 0 -0 0</pose>
      <inertial>
        <pose>0.022 0 0 0 -0 0</pose>
        <mass>0.01</mass>
        <inertia>
          <ixx>7.89997e-07</ixx>
          <ixy>0</ixy>
          <ixz>0</ixz>
          <iyy>7.89997e-07</iyy>
          <iyz>0</iyz>
          <izz>8e-08</izz>
        </inertia>
      </inertial>
      <collision name='j2n6s300_link_finger_tip_2_collision'>
        <pose>0 0 0 0 -0 0</pose>
        <geometry>
          <mesh>
            <scale>1 1 1</scale>
            <uri>model://j2n6s300/meshes/finger_distal.dae</uri>
          </mesh>
        </geometry>
      </collision>
      <visual name='j2n6s300_link_finger_tip_2_visual'>
        <pose>0 0 0 0 -0 0</pose>
        <geometry>
          <mesh>
            <scale>1 1 1</scale>
            <uri>model://j2n6s300/meshes/finger_distal.dae</uri>
          </mesh>
        </geometry>
      </visual>
    </link>
    <joint name='j2n6s300_joint_finger_3' type='fixed'>
      <pose relative_to='j2n6s300_link_6'>-0.02226 -0.02707 -0.11482 -1.5708 0.649262 -1.75545</pose>
      <parent>j2n6s300_link_6</parent>
      <child>j2n6s300_link_finger_3</child>
      <axis>
        <xyz>0 0 1</xyz>
        <limit>
          <lower>0</lower>
          <upper>1.51</upper>
          <effort>2</effort>
          <velocity>1</velocity>
        </limit>
        <dynamics>
          <spring_reference>0</spring_reference>
          <spring_stiffness>0</spring_stiffness>
        </dynamics>
      </axis>
    </joint>
    <link name='j2n6s300_link_finger_3'>
      <pose relative_to='j2n6s300_joint_finger_3'>0 0 0 0 -0 0</pose>
      <inertial>
        <pose>0.022 0 0 0 -0 0</pose>
        <mass>0.01</mass>
        <inertia>
          <ixx>7.89997e-07</ixx>
          <ixy>0</ixy>
          <ixz>0</ixz>
          <iyy>7.89997e-07</iyy>
          <iyz>0</iyz>
          <izz>8e-08</izz>
        </inertia>
      </inertial>
      <collision name='j2n6s300_link_finger_3_collision'>
        <pose>0 0 0 0 -0 0</pose>
        <geometry>
          <mesh>
            <scale>1 1 1</scale>
            <uri>model://j2n6s300/meshes/finger_proximal.dae</uri>
          </mesh>
        </geometry>
      </collision>
      <visual name='j2n6s300_link_finger_3_visual'>
        <pose>0 0 0 0 -0 0</pose>
        <geometry>
          <mesh>
            <scale>1 1 1</scale>
            <uri>model://j2n6s300/meshes/finger_proximal.dae</uri>
          </mesh>
        </geometry>
      </visual>
    </link>
    <joint name='j2n6s300_joint_finger_tip_3' type='fixed'>
      <pose relative_to='j2n6s300_link_finger_3'>0.044 -0.003 0 0 -0 0</pose>
      <parent>j2n6s300_link_finger_3</parent>
      <child>j2n6s300_link_finger_tip_3</child>
      <axis>
        <xyz>0 0 1</xyz>
        <limit>
          <lower>0</lower>
          <upper>2</upper>
          <effort>2</effort>
          <velocity>1</velocity>
        </limit>
        <dynamics>
          <spring_reference>0</spring_reference>
          <spring_stiffness>0</spring_stiffness>
        </dynamics>
      </axis>
    </joint>
    <link name='j2n6s300_link_finger_tip_3'>
      <pose relative_to='j2n6s300_joint_finger_tip_3'>0 0 0 0 -0 0</pose>
      <inertial>
        <pose>0.022 0 0 0 -0 0</pose>
        <mass>0.01</mass>
        <inertia>
          <ixx>7.89997e-07</ixx>
          <ixy>0</ixy>
          <ixz>0</ixz>
          <iyy>7.89997e-07</iyy>
          <iyz>0</iyz>
          <izz>8e-08</izz>
        </inertia>
      </inertial>
      <collision name='j2n6s300_link_finger_tip_3_collision'>
        <pose>0 0 0 0 -0 0</pose>
        <geometry>
          <mesh>
            <scale>1 1 1</scale>
            <uri>model://j2n6s300/meshes/finger_distal.dae</uri>
          </mesh>
        </geometry>
      </collision>
      <visual name='j2n6s300_link_finger_tip_3_visual'>
        <pose>0 0 0 0 -0 0</pose>
        <geometry>
          <mesh>
            <scale>1 1 1</scale>
            <uri>model://j2n6s300/meshes/finger_distal.dae</uri>
          </mesh>
        </geometry>
      </visual>
    </link>
    <!-- <plugin name='gazebo_ros_control' filename='libgazebo_ros_control.so'>
      <robotNamespace>j2n6s300</robotNamespace>
      <robotSimType>gazebo_ros_control/DefaultRobotHWSim</robotSimType>
      <legacyModeNS>1</legacyModeNS>
    </plugin>
    <plugin name='ft_sensor' filename='libgazebo_ros_ft_sensor.so'>
      <updateRate>30.0</updateRate>
      <topicName>j2n6s300_joint_1_ft_sensor_topic</topicName>
      <jointName>j2n6s300_joint_1</jointName>
    </plugin>
    <plugin name='ft_sensor' filename='libgazebo_ros_ft_sensor.so'>
      <updateRate>30.0</updateRate>
      <topicName>j2n6s300_joint_2_ft_sensor_topic</topicName>
      <jointName>j2n6s300_joint_2</jointName>
    </plugin>
    <plugin name='ft_sensor' filename='libgazebo_ros_ft_sensor.so'>
      <updateRate>30.0</updateRate>
      <topicName>j2n6s300_joint_3_ft_sensor_topic</topicName>
      <jointName>j2n6s300_joint_3</jointName>
    </plugin>
    <plugin name='ft_sensor' filename='libgazebo_ros_ft_sensor.so'>
      <updateRate>30.0</updateRate>
      <topicName>j2n6s300_joint_4_ft_sensor_topic</topicName>
      <jointName>j2n6s300_joint_4</jointName>
    </plugin>
    <plugin name='ft_sensor' filename='libgazebo_ros_ft_sensor.so'>
      <updateRate>30.0</updateRate>
      <topicName>j2n6s300_joint_5_ft_sensor_topic</topicName>
      <jointName>j2n6s300_joint_5</jointName>
    </plugin>
    <static>0</static>
    <plugin name='ft_sensor' filename='libgazebo_ros_ft_sensor.so'>
      <updateRate>30.0</updateRate>
      <topicName>j2n6s300_joint_6_ft_sensor_topic</topicName>
      <jointName>j2n6s300_joint_6</jointName>
    </plugin> -->
  </model>

  </model>
</sdf>
